<mujoco model="ur5">
    <compiler angle="radian" />
    <size njmax="600" nconmax="150" nstack="300000"/>
    <option timestep="0.002" gravity ="0 0 -9.81" />

    <default>
        <site rgba="0.8 0.6 0.7 0.3" type="ellipsoid" group="3"/>
        <geom contype='1' conaffinity='1' condim='4'  margin="1e-3" solref=".01 1" solimp=".99 .99 .01" />
        <joint armature="0.01" damping=".1"/>
        <default class="UR5">
            <joint damping='10'/>
        </default>
        <default class="UR5e">
            <joint damping='45'/>
        </default>
        <default class="GRIPPER">
            <joint damping='5'/>
        </default>
    </default>

    <asset>
    
        <material name="green" rgba="0 0.9 0 1" />
        <material name="blue" rgba="0 0 0.9 1" />
        <texture type="skybox" builtin="gradient" rgb1="1 1 1" rgb2=".6 .8 1" width="10" height="10"/>
<!--        <material name="grid" texture="grid" texrepeat="1 1 1" texuniform="true" reflectance=".2" />-->
        <mesh name="base" file="base.stl" />
        <mesh name="shoulder" file="shoulder.stl" />
        <mesh name="upperarm" file="upperarm.stl" />
        <mesh name="forearm" file="forearm.stl" />
        <mesh name="wrist1" file="wrist1.stl" />
        <mesh name="wrist2" file="wrist2.stl" />
        <mesh name="wrist3" file="wrist3.stl" />
                <!--Textures-->
        <texture name="ur5_tex"     type="2d"       builtin="flat" height="32" width="32" rgb1="0.45 0.45 0.45" />
        <texture name="gripper_tex" type="2d"       builtin="flat" height="32" width="32" rgb1="0.45 0.45 0.45" rgb2="0 0 0"/>
        <texture name="bench_tex"   type="2d"       builtin="flat" height="32" width="32" rgb1="0.7 0.7 0.7" />
        <texture name="sky_tex"     type="skybox"   builtin="gradient" width="100" height="100" rgb1="1 1 1" rgb2="0.3 0.3 0.8" />
        <texture name="texgeom"     type="cube"     builtin="flat" mark="cross" width="127" height="1278" rgb1="0.8 0.6 0.4" rgb2="0.8 0.6 0.4" markrgb="1 1 1" random="0.01" />
        <texture name="floor_tex"   type="2d"        builtin="checker" rgb1=".2 .3 .4" rgb2=".1 .2 .3" width="100" height="100" />
        <!--Materials-->
        <material name="ur5_mat"        texture="ur5_tex"   shininess="0.9" specular="0.75" reflectance="0.3"/>
        <material name="gripper_mat"    texture="gripper_tex"   shininess="0.9" specular="0.75" reflectance="0.4"/>
        <material name='floor_mat'      texture="floor_tex"  shininess="0.8" texrepeat="10 10" specular="0.7"  reflectance="0.5" />
        <material name='geom'           texture="texgeom"   texuniform="true" />
    </asset>
    
    <worldbody>
    <geom type="mesh"  mesh="base" material="ur5_mat"/>
    <body name="shoulder_link" pos="0 0 0.089159">
        <inertial pos="0 0 0" mass="3.7" diaginertia="0.0102675 0.0102675 0.00666" />
        <joint name="shoulder_pan_joint" class="UR5" pos="0 0 0" axis="0 0 1" limited="true" range="-6.28 6.28" />
        <geom type="mesh"  mesh="shoulder" material="ur5_mat"/>
        <body name="upper_arm_link" pos="0 0.13585 0" quat="0.707107 0 0.707107 0">
            <inertial pos="0 0 0.28" mass="8.393" diaginertia="0.226891 0.226891 0.0151074" />
            <joint name="shoulder_lift_joint" class="UR5" pos="0 0 0" axis="0 1 0" limited="true" range="-6.28 6.28" /> <!--Range= -3.14159 3.14159-->
            <geom type="mesh"  mesh="upperarm" material="ur5_mat"/>
            <body name="forearm_link" pos="0 -0.1197 0.425">
                <inertial pos="0 0 0.25" mass="2.275" diaginertia="0.0494433 0.0494433 0.004095" />
                <joint name="elbow_joint" class="UR5" pos="0 0 0" axis="0 1 0" limited="true" range="-6.28 6.28" />
                <geom type="mesh"  mesh="forearm" material="ur5_mat"/>
                <body name="wrist_1_link" pos="0 0 0.39225" quat="0.707107 0 0.707107 0">
                    <inertial pos="0 0 0" quat="0.5 0.5 -0.5 0.5" mass="1.219" diaginertia="0.21942 0.111173 0.111173" />
                    <joint name="wrist_1_joint" class="UR5e" pos="0 0 0" axis="0 1 0" limited="true" range="-6.28 6.28" />
                    <geom type="mesh"  mesh="wrist1" material="ur5_mat"/>
                    <body name="wrist_2_link" pos="0 0.093 0">
                        <inertial pos="0 0 0" quat="0.5 0.5 -0.5 0.5" mass="1.219" diaginertia="0.21942 0.111173 0.111173" />
                        <joint name="wrist_2_joint" class="UR5e" pos="0 0 0" axis="0 0 1" limited="true" range="-6.28 6.28" />
                        <geom type="mesh"  mesh="wrist2" material="ur5_mat"/>
                        <body name="wrist_3_link" pos="0 0 0.09465">
                            <inertial pos="0 0 0" quat="0.5 0.5 -0.5 0.5" mass="0.1879" diaginertia="0.033822 0.0171365 0.0171365" />
                            <joint name="wrist_3_joint" class="UR5e" pos="0 0 0" axis="0 1 0" limited="true" range="-6.28 6.28" />
                            <geom type="mesh"  mesh="wrist3" material="ur5_mat"/>
                            <body name="ee_link" pos="0 0.0823 0" quat="0.707107 0 0 0.707107">
                                <inertial pos="-0.01 0 0" mass="0.001" diaginertia="1.66667e-08 1.66667e-08 1.66667e-08" />
                                <geom size="0.005 0.005 0.005" pos="-0.0025 0 0" type="box" />
                                <site name="endpos" type="sphere" size="1" pos="0 0 0"/>
                            </body>
                            </body>
                        </body>
                    </body>
                </body>
            </body>
        </body>
    </worldbody>
    <actuator>
        <!-- 每个关节配置三种执行器模式 -->
        <motor name="trq_ctrl1" joint="shoulder_pan_joint" ctrllimited="true" ctrlrange="-100 100" />
        <motor name="trq_ctrl2" joint="shoulder_lift_joint" ctrllimited="true" ctrlrange="-200 200" />
        <motor name="trq_ctrl3" joint="elbow_joint" ctrllimited="true" ctrlrange="-200 200" />
        <motor name="trq_ctrl4" joint="wrist_1_joint" ctrllimited="true" ctrlrange="-100 100" />
        <motor name="trq_ctrl5" joint="wrist_2_joint" ctrllimited="true" ctrlrange="-100 100" />
        <motor name="trq_ctrl6" joint="wrist_3_joint" ctrllimited="true" ctrlrange="-100 100" />
    </actuator>

    <sensor>
        <!-- 关节位置传感器 -->
        <jointpos name="joint1_pos" joint="shoulder_pan_joint"/>
        <jointpos name="joint2_pos" joint="shoulder_lift_joint"/>
        <jointpos name="joint3_pos" joint="elbow_joint"/>
        <jointpos name="joint4_pos" joint="wrist_1_joint"/>
        <jointpos name="joint5_pos" joint="wrist_2_joint"/>
        <jointpos name="joint6_pos" joint="wrist_3_joint"/>
        
        <!-- 关节速度传感器 -->
        <jointvel name="joint1_vel" joint="shoulder_pan_joint"/>
        <jointvel name="joint2_vel" joint="shoulder_lift_joint"/>
        <jointvel name="joint3_vel" joint="elbow_joint"/>
        <jointvel name="joint4_vel" joint="wrist_1_joint"/>
        <jointvel name="joint5_vel" joint="wrist_2_joint"/>
        <jointvel name="joint6_vel" joint="wrist_3_joint"/>
        
    <!-- <framepos name="ee_pos" objtype="site" objname="endpos"/> -->
    <framelinvel name="framelinvel3" objtype="site" objname="endpos"/>
    <frameangvel name="frameangvel3" objtype="site" objname="endpos"/>
    <framepos name="ee_pos" objtype="site" objname="endpos"/>
    <framequat name="ee_quat" objtype="site" objname="endpos"/>
    </sensor>
</mujoco>
    <!-- <actuator>
	    <position name="pos_ctrl1" joint="shoulder_pan_joint" kp="10" />
        <position name="pos_ctrl2" joint="shoulder_lift_joint" kp="10" />
        <position name="pos_ctrl3" joint="elbow_joint" kp="10" />
        <position name="pos_ctrl4" joint="wrist_1_joint" kp="10" />
        <position name="pos_ctrl5" joint="wrist_2_joint" kp="10" />
        <position name="pos_ctrl6" joint="wrist_3_joint" kp="10" />
        <motor name="trq_ctrl1" joint="shoulder_pan_joint" ctrllimited="true" ctrlrange="-100 100" />
        <motor name="trq_ctrl2" joint="shoulder_lift_joint" ctrllimited="true" ctrlrange="-200 200" />
        <motor name="trq_ctrl3" joint="elbow_joint" ctrllimited="true" ctrlrange="-200 200" />
        <motor name="trq_ctrl4" joint="wrist_1_joint" ctrllimited="true" ctrlrange="-100 100" />
        <motor name="trq_ctrl5" joint="wrist_2_joint" ctrllimited="true" ctrlrange="-100 100" />
        <motor name="trq_ctrl6" joint="wrist_3_joint" ctrllimited="true" ctrlrange="-100 100" />
	</actuator> -->
    <!-- <actuator>
	    <motor name="trq_ctrl1" joint="shoulder_pan_joint" ctrllimited="true" ctrlrange="-100 100" />
        <motor name="trq_ctrl2" joint="shoulder_lift_joint" ctrllimited="true" ctrlrange="-200 200" />
        <motor name="trq_ctrl3" joint="elbow_joint" ctrllimited="true" ctrlrange="-200 200" />
        <motor name="trq_ctrl4" joint="wrist_1_joint" ctrllimited="true" ctrlrange="-100 100" />
        <motor name="trq_ctrl5" joint="wrist_2_joint" ctrllimited="true" ctrlrange="-100 100" />
        <motor name="trq_ctrl6" joint="wrist_3_joint" ctrllimited="true" ctrlrange="-100 100" />
	</actuator> -->
    <!-- <actuator>
	    <position name="pos_ctrl1" joint="shoulder_pan_joint" kp="10" />
	    <velocity name="vel_ctrl1" joint="shoulder_pan_joint" kv="1" />
	    <motor name="trq_ctrl1" joint="shoulder_pan_joint" ctrllimited="true" ctrlrange="-100 100" />
        <position name="pos_ctrl2" joint="shoulder_lift_joint" kp="10" />
	    <velocity name="vel_ctrl2" joint="shoulder_lift_joint" kv="1" />
	    <motor name="trq_ctrl2" joint="shoulder_lift_joint" ctrllimited="true" ctrlrange="-200 200" />
        <position name="pos_ctrl3" joint="elbow_joint" kp="10" />
	    <velocity name="vel_ctrl3" joint="elbow_joint" kv="1" />
	    <motor name="trq_ctrl3" joint="elbow_joint" ctrllimited="true" ctrlrange="-200 200" />
        <position name="pos_ctrl4" joint="wrist_1_joint" kp="10" />
	    <velocity name="vel_ctrl4" joint="wrist_1_joint" kv="1" />
	    <motor name="trq_ctrl4" joint="wrist_1_joint" ctrllimited="true" ctrlrange="-100 100" />
        <position name="pos_ctrl5" joint="wrist_2_joint" kp="10" />
	    <velocity name="vel_ctrl5" joint="wrist_2_joint" kv="1" />
	    <motor name="trq_ctrl5" joint="wrist_2_joint" ctrllimited="true" ctrlrange="-100 100" />
        <position name="pos_ctrl6" joint="wrist_3_joint" kp="10" />
	    <velocity name="vel_ctrl6" joint="wrist_3_joint" kv="1" />mj_step
	    <motor name="trq_ctrl6" joint="wrist_3_joint" ctrllimited="true" ctrlrange="-100 100" />
	</actuator> -->
